Workbook

Sheet Cover
A1: Marico Limited (NSE: MARICO) – Three-Statement Model & DCF Valuation
A2: ₹ crore unless stated | Fiscal year ends 31 March | Historicals FY22A–FY26A (FY22 partial) | Forecast FY27E–FY31E | Prepared 23-Oct-2026
A4: VALUATION SUMMARY
A5: Scenario | C5: =Assumptions!D3 -> Base case
A6: Implied value per share (₹) | C6: =DCF!C54 -> 319.97159
A7: Current share price (₹) | C7: =DCF!C55 -> 775
A8: Implied upside / (downside) | C8: =DCF!C56 -> -0.58713343
A9: Enterprise value (₹ cr) | C9: =DCF!C44 -> 41947.137
A10: Equity value (₹ cr) | C10: =DCF!C52 -> 41627.137
A11: WACC | C11: =DCF!C7 -> 0.11469908
A12: Terminal growth rate | C12: =DCF!C8 -> 0.06
A13: Terminal value % of EV | C13: =DCF!C45 -> 0.80720833
A14: Implied EV / FY27E EBITDA | C14: =DCF!C57 -> 15.220775
A15: Market-implied EV / FY27E EBITDA | C15: =DCF!C59 -> 36.700962
A16: Model integrity (Checks sheet) | C16: =Checks!M28 -> ALL CHECKS PASS
A18: WORKBOOK STRUCTURE
A19: Assumptions – scenario selector (cell C3) and Bear / Base / Bull drivers for FY27E–FY31E, with historical ratios for reference
A20: Historicals – reported consolidated P&L, balance sheet, cash flow and segment data, each figure source-noted
A21: Model – revenue build (India volume × price/mix; International CCG × FX), integrated IS / BS / CF, key ratios
A22: WACC – CAPM cost of equity, cost of debt, market-value weights
A23: DCF – unlevered FCF, perpetual-growth terminal value, EV-to-equity bridge, WACC × g and WACC × margin sensitivities
A24: Checks – balance sheet, cash, net income, equity roll-forward and DCF consistency checks with master status
A26: COLOUR CONVENTIONS
A27: 1234 | B27: Hardcoded input / reported figure (sources on Historicals rows 128–132 and WACC column D)
A28: 1234 | B28: Formula / calculation
A29: 1234 | B29: Link to another worksheet
B30: Key output / base case
A32: KEY SOURCES
A33: FY25–FY26: Marico Integrated Annual Report FY2025-26 – https://marico.com/investorspdf/Marico_Annual_Report_FY26.pdf
A34: FY23–FY24: Audited consolidated results FY2023-24 (Board Meeting Update, 6-May-2024) – https://marico.com/investorspdf/Board_Meeting_Update_-_May_6,_2024.pdf
A35: FY26 KPIs: Q4FY26 Results media release – https://marico.com/investorspdf/Media_Release_Q4FY26.pdf
A36: Market data (unofficial aggregators – verify): share price (Trendlyne/NSE close 22-Oct-26), beta (Business Today), 10Y G-sec (Trading Economics, 23-Oct-26)
A38: LIMITATIONS & MODELLING NOTES
A39: • FY22: full audited statements could not be retrieved from an official source; only revenue and EBITDA (FY26 Annual Report highlights) are shown. No figures were estimated.
A40: • Forecast balance sheet is condensed: treasury investments, goodwill, leases, NCI put obligation and other non-current items held flat; surplus cash accumulates in cash.
A41: • Leases: lease liabilities held flat; ROU additions are treated as part of capex, so lease cash costs are captured in UFCF.
A42: • Other income = yield on opening cash & treasury; finance cost = rate on opening debt & leases (no circularity). Treasury income is excluded from EBIT/UFCF; cash is added in the bridge.
A43: • Bridge deducts borrowings, lease liabilities, the ₹2,055 cr obligation to buy NCI (Note 13(b)) and book NCI. Q2FY27 results (board meeting 2-Nov-2026) are not yet reflected.
A44: • Q1FY27 trends and FY27 guidance used for assumption rationale are taken from company commentary as reported in press; verify against Marico's Q1FY27 Information Update.

Sheet Assumptions
A1: Marico Limited – Forecast Assumptions
A2: Blue = editable input | Selected case (rows 7–29) feeds the model | Historical ratios shown for reference (green = linked)
A3: Scenario selector (1 = Bear, 2 = Base, 3 = Bull) | C3: 2 | D3: =CHOOSE(C3,"Bear case","Base case","Bull case") -> Base case | E3: ← Enter 1 = Bear, 2 = Base, 3 = Bull; all statements, DCF and sensitivities update
A5: SELECTED CASE – DRIVES MODEL
A6: Driver | B6: Unit | C6: FY22A | D6: FY23A | E6: FY24A | F6: FY25A | G6: FY26A | H6: FY27E | I6: FY28E | J6: FY29E | K6: FY30E | L6: FY31E
A7: India underlying volume growth | B7: % | G7: =Historicals!G125 -> 0.08 | H7: =CHOOSE($C$3,H34,H61,H88) -> 0.08 | I7: =CHOOSE($C$3,I34,I61,I88) -> 0.07 | J7: =CHOOSE($C$3,J34,J61,J88) -> 0.07 | K7: =CHOOSE($C$3,K34,K61,K88) -> 0.065 | L7: =CHOOSE($C$3,L34,L61,L88) -> 0.06
A8: India price / mix | B8: % | G8: =(1+Model!G9)/(1+Historicals!G125)-1 -> 0.18144038 | H8: =CHOOSE($C$3,H35,H62,H89) -> 0.03 | I8: =CHOOSE($C$3,I35,I62,I89) -> 0.03 | J8: =CHOOSE($C$3,J35,J62,J89) -> 0.035 | K8: =CHOOSE($C$3,K35,K62,K89) -> 0.035 | L8: =CHOOSE($C$3,L35,L62,L89) -> 0.035
A9: International constant-currency growth | B9: % | G9: =Historicals!G126 -> 0.2 | H9: =CHOOSE($C$3,H36,H63,H90) -> 0.15 | I9: =CHOOSE($C$3,I36,I63,I90) -> 0.13 | J9: =CHOOSE($C$3,J36,J63,J90) -> 0.12 | K9: =CHOOSE($C$3,K36,K63,K90) -> 0.11 | L9: =CHOOSE($C$3,L36,L63,L90) -> 0.1
A10: International FX translation impact | B10: % | G10: =(1+Model!G11)/(1+Historicals!G126)-1 -> -0.0006737719 | H10: =CHOOSE($C$3,H37,H64,H91) -> -0.01 | I10: =CHOOSE($C$3,I37,I64,I91) -> -0.01 | J10: =CHOOSE($C$3,J37,J64,J91) -> -0.01 | K10: =CHOOSE($C$3,K37,K64,K91) -> -0.01 | L10: =CHOOSE($C$3,L37,L64,L91) -> -0.01
A11: Material cost (raw & packing materials) | B11: % rev | D11: =Model!D96 -> 0.54803359 | E11: =Model!E96 -> 0.49186781 | F11: =Model!F96 -> 0.49746099 | G11: =Model!G96 -> 0.55535964 | H11: =CHOOSE($C$3,H38,H65,H92) -> 0.535 | I11: =CHOOSE($C$3,I38,I65,I92) -> 0.525 | J11: =CHOOSE($C$3,J38,J65,J92) -> 0.52 | K11: =CHOOSE($C$3,K38,K65,K92) -> 0.52 | L11: =CHOOSE($C$3,L38,L65,L92) -> 0.52
A12: Advertising & sales promotion | B12: % rev | D12: =Model!D93 -> 0.08623515 | E12: =Model!E93 -> 0.09862219 | F12: =Model!F93 -> 0.10414551 | G12: =Model!G93 -> 0.095584454 | H12: =CHOOSE($C$3,H39,H66,H93) -> 0.103 | I12: =CHOOSE($C$3,I39,I66,I93) -> 0.103 | J12: =CHOOSE($C$3,J39,J66,J93) -> 0.103 | K12: =CHOOSE($C$3,K39,K66,K93) -> 0.103 | L12: =CHOOSE($C$3,L39,L66,L93) -> 0.103
A13: Employee cost | B13: % rev | D13: =Model!D94 -> 0.066878329 | E13: =Model!E94 -> 0.07697089 | F13: =Model!F94 -> 0.076724218 | G13: =Model!G94 -> 0.067298509 | H13: =CHOOSE($C$3,H40,H67,H94) -> 0.068 | I13: =CHOOSE($C$3,I40,I67,I94) -> 0.068 | J13: =CHOOSE($C$3,J40,J67,J94) -> 0.068 | K13: =CHOOSE($C$3,K40,K67,K94) -> 0.068 | L13: =CHOOSE($C$3,L40,L67,L94) -> 0.068
A14: Other expenses (excl. A&P) | B14: % rev | D14: =Model!D95 -> 0.11347808 | E14: =Model!E95 -> 0.12265617 | F14: =Model!F95 -> 0.12418059 | G14: =Model!G95 -> 0.11071927 | H14: =CHOOSE($C$3,H41,H68,H95) -> 0.113 | I14: =CHOOSE($C$3,I41,I68,I95) -> 0.113 | J14: =CHOOSE($C$3,J41,J68,J95) -> 0.113 | K14: =CHOOSE($C$3,K41,K68,K95) -> 0.113 | L14: =CHOOSE($C$3,L41,L68,L95) -> 0.113
A15: Depreciation & amortisation | B15: % rev | D15: =Model!D92 -> 0.015874642 | E15: =Model!E92 -> 0.016367969 | F15: =Model!F92 -> 0.016434309 | G15: =Model!G92 -> 0.014840937 | H15: =CHOOSE($C$3,H42,H69,H96) -> 0.0155 | I15: =CHOOSE($C$3,I42,I69,I96) -> 0.0155 | J15: =CHOOSE($C$3,J42,J69,J96) -> 0.0155 | K15: =CHOOSE($C$3,K42,K69,K96) -> 0.0155 | L15: =CHOOSE($C$3,L42,L69,L96) -> 0.0155
A16: Capex (incl. ROU additions) | B16: % rev | D16: =Model!D91 -> 0.018639902 | E16: =Model!E91 -> 0.015849995 | F16: =Model!F91 -> 0.01486474 | G16: =Model!G91 -> 0.023436926 | H16: =CHOOSE($C$3,H43,H70,H97) -> 0.022 | I16: =CHOOSE($C$3,I43,I70,I97) -> 0.022 | J16: =CHOOSE($C$3,J43,J70,J97) -> 0.022 | K16: =CHOOSE($C$3,K43,K70,K97) -> 0.022 | L16: =CHOOSE($C$3,L43,L70,L97) -> 0.022
A17: Trade receivable days | B17: days rev | D17: =Model!D86 -> 37.942954 | E17: =Model!E86 -> 40.421113 | F17: =Model!F86 -> 42.832148 | G17: =Model!G86 -> 34.968775 | H17: =CHOOSE($C$3,H44,H71,H98) -> 37 | I17: =CHOOSE($C$3,I44,I71,I98) -> 37 | J17: =CHOOSE($C$3,J44,J71,J98) -> 37 | K17: =CHOOSE($C$3,K44,K71,K98) -> 37 | L17: =CHOOSE($C$3,L44,L71,L98) -> 37
A18: Inventory days | B18: days mat. | D18: =Model!D87 -> 83.559148 | E18: =Model!E87 -> 102.7043 | F18: =Model!F87 -> 83.662769 | G18: =Model!G87 -> 77.790052 | H18: =CHOOSE($C$3,H45,H72,H99) -> 80 | I18: =CHOOSE($C$3,I45,I72,I99) -> 80 | J18: =CHOOSE($C$3,J45,J72,J99) -> 80 | K18: =CHOOSE($C$3,K45,K72,K99) -> 80 | L18: =CHOOSE($C$3,L45,L72,L99) -> 80
A19: Trade payable days | B19: days mat. | D19: =Model!D88 -> 99.04317 | E19: =Model!E88 -> 121.53854 | F19: =Model!F88 -> 88.472532 | G19: =Model!G88 -> 78.900648 | H19: =CHOOSE($C$3,H46,H73,H100) -> 80 | I19: =CHOOSE($C$3,I46,I73,I100) -> 80 | J19: =CHOOSE($C$3,J46,J73,J100) -> 80 | K19: =CHOOSE($C$3,K46,K73,K100) -> 80 | L19: =CHOOSE($C$3,L46,L73,L100) -> 80
A20: Other current assets | B20: % rev | D20: =Model!D89 -> 0.025194592 | E20: =Model!E89 -> 0.041023516 | F20: =Model!F89 -> 0.038685255 | G20: =Model!G89 -> 0.037028874 | H20: =CHOOSE($C$3,H47,H74,H101) -> 0.037 | I20: =CHOOSE($C$3,I47,I74,I101) -> 0.037 | J20: =CHOOSE($C$3,J47,J74,J101) -> 0.037 | K20: =CHOOSE($C$3,K47,K74,K101) -> 0.037 | L20: =CHOOSE($C$3,L47,L74,L101) -> 0.037
A21: Other current liabilities | B21: % rev | D21: =Model!D90 -> 0.047316673 | E21: =Model!E90 -> 0.04547809 | F21: =Model!F90 -> 0.049395254 | G21: =Model!G90 -> 0.068253618 | H21: =CHOOSE($C$3,H48,H75,H102) -> 0.06 | I21: =CHOOSE($C$3,I48,I75,I102) -> 0.06 | J21: =CHOOSE($C$3,J48,J75,J102) -> 0.06 | K21: =CHOOSE($C$3,K48,K75,K102) -> 0.06 | L21: =CHOOSE($C$3,L48,L75,L102) -> 0.06
A22: Effective tax rate | B22: % PBT | D22: =Model!D32 -> 0.24153758 | E22: =Model!E32 -> 0.22457408 | F22: =Model!F32 -> 0.21644612 | G22: =Model!G32 -> 0.2037769 | H22: =CHOOSE($C$3,H49,H76,H103) -> 0.23 | I22: =CHOOSE($C$3,I49,I76,I103) -> 0.23 | J22: =CHOOSE($C$3,J49,J76,J103) -> 0.23 | K22: =CHOOSE($C$3,K49,K76,K103) -> 0.23 | L22: =CHOOSE($C$3,L49,L76,L103) -> 0.23
A23: Non-controlling interest share of PAT | B23: % PAT | D23: =Model!D97 -> 0.015128593 | E23: =Model!E97 -> 0.013981358 | F23: =Model!F97 -> 0.017490953 | G23: =Model!G97 -> 0.028130171 | H23: =CHOOSE($C$3,H50,H77,H104) -> 0.025 | I23: =CHOOSE($C$3,I50,I77,I104) -> 0.025 | J23: =CHOOSE($C$3,J50,J77,J104) -> 0.025 | K23: =CHOOSE($C$3,K50,K77,K104) -> 0.025 | L23: =CHOOSE($C$3,L50,L77,L104) -> 0.025
A24: Dividend payout – owners | B24: % PAT | D24: =Model!D98 -> 0.44700461 | E24: =Model!E98 -> 0.8298447 | F24: =Model!F98 -> 0.27808471 | G24: =Model!G98 -> 0.5153235 | H24: =CHOOSE($C$3,H51,H78,H105) -> 0.8 | I24: =CHOOSE($C$3,I51,I78,I105) -> 0.8 | J24: =CHOOSE($C$3,J51,J78,J105) -> 0.8 | K24: =CHOOSE($C$3,K51,K78,K105) -> 0.8 | L24: =CHOOSE($C$3,L51,L78,L105) -> 0.8
A25: Dividend payout – NCI | B25: % NCI PAT | D25: =Model!D99 -> 1.25 | E25: =Model!E99 -> 0 | F25: =Model!F99 -> 1.6206897 | G25: =Model!G99 -> 1.5882353 | H25: =CHOOSE($C$3,H52,H79,H106) -> 1 | I25: =CHOOSE($C$3,I52,I79,I106) -> 1 | J25: =CHOOSE($C$3,J52,J79,J106) -> 1 | K25: =CHOOSE($C$3,K52,K79,K106) -> 1 | L25: =CHOOSE($C$3,L52,L79,L106) -> 1
A26: Yield on treasury assets (opening) | B26: % | E26: =Model!E100 -> 0.076673866 | F26: =Model!F100 -> 0.13462783 | G26: =Model!G100 -> 0.086185044 | H26: =CHOOSE($C$3,H53,H80,H107) -> 0.07 | I26: =CHOOSE($C$3,I53,I80,I107) -> 0.07 | J26: =CHOOSE($C$3,J53,J80,J107) -> 0.07 | K26: =CHOOSE($C$3,K53,K80,K107) -> 0.07 | L26: =CHOOSE($C$3,L53,L80,L107) -> 0.07
A27: Interest rate on debt & leases (opening) | B27: % | E27: =Model!E101 -> 0.12006579 | F27: =Model!F101 -> 0.10037879 | G27: =Model!G101 -> 0.09566787 | H27: =CHOOSE($C$3,H54,H81,H108) -> 0.09 | I27: =CHOOSE($C$3,I54,I81,I108) -> 0.09 | J27: =CHOOSE($C$3,J54,J81,J108) -> 0.09 | K27: =CHOOSE($C$3,K54,K81,K108) -> 0.09 | L27: =CHOOSE($C$3,L54,L81,L108) -> 0.09
A28: Net borrowings / (repayment) | B28: ₹ cr | D28: =Model!D74 -> 128 | E28: =Model!E74 -> -91 | F28: =Model!F74 -> -5 | G28: =Model!G74 -> -24 | H28: =CHOOSE($C$3,H55,H82,H109) -> 0 | I28: =CHOOSE($C$3,I55,I82,I109) -> 0 | J28: =CHOOSE($C$3,J55,J82,J109) -> 0 | K28: =CHOOSE($C$3,K55,K82,K109) -> 0 | L28: =CHOOSE($C$3,L55,L82,L109) -> 0
A29: Terminal growth rate (perpetuity) | B29: % | H29: =CHOOSE($C$3,H56,H83,H110) -> 0.06
A32: BEAR CASE
A33: Driver | B33: Unit | C33: FY22A | D33: FY23A | E33: FY24A | F33: FY25A | G33: FY26A | H33: FY27E | I33: FY28E | J33: FY29E | K33: FY30E | L33: FY31E
A34: India underlying volume growth | B34: % | H34: 0.05 | I34: 0.05 | J34: 0.05 | K34: 0.045 | L34: 0.04
A35: India price / mix | B35: % | H35: 0.01 | I35: 0.02 | J35: 0.025 | K35: 0.025 | L35: 0.025
A36: International constant-currency growth | B36: % | H36: 0.1 | I36: 0.09 | J36: 0.08 | K36: 0.08 | L36: 0.07
A37: International FX translation impact | B37: % | H37: -0.03 | I37: -0.03 | J37: -0.03 | K37: -0.03 | L37: -0.03
A38: Material cost (raw & packing materials) | B38: % rev | H38: 0.555 | I38: 0.545 | J38: 0.54 | K38: 0.54 | L38: 0.54
A39: Advertising & sales promotion | B39: % rev | H39: 0.108 | I39: 0.108 | J39: 0.108 | K39: 0.108 | L39: 0.108
A40: Employee cost | B40: % rev | H40: 0.07 | I40: 0.07 | J40: 0.07 | K40: 0.07 | L40: 0.07
A41: Other expenses (excl. A&P) | B41: % rev | H41: 0.116 | I41: 0.116 | J41: 0.116 | K41: 0.116 | L41: 0.116
A42: Depreciation & amortisation | B42: % rev | H42: 0.0155 | I42: 0.0155 | J42: 0.0155 | K42: 0.0155 | L42: 0.0155
A43: Capex (incl. ROU additions) | B43: % rev | H43: 0.025 | I43: 0.025 | J43: 0.025 | K43: 0.025 | L43: 0.025
...

Sheet Historicals
A1: Marico Limited – Reported Consolidated Financial Statements
A2: ₹ crore unless stated | Fiscal year ends 31 March | Blue = reported figure (sources listed from row 128); black = formula
A4: ₹ crore | C4: FY22A | D4: FY23A | E4: FY24A | F4: FY25A | G4: FY26A
A5: INCOME STATEMENT
A6: Revenue from operations | C6: 9512 | D6: 9764 | E6: 9653 | F6: 10831 | G6: 13611
A7: Other income | D7: 144 | E7: 142 | F7: 208 | G7: 204
A8: Total income | D8: =D6+D7 -> 9908 | E8: =E6+E7 -> 9795 | F8: =F6+F7 -> 11039 | G8: =G6+G7 -> 13815
A9: Cost of materials consumed | D9: 4649 | E9: 3941 | F9: 4572 | G9: 6197
A10: Purchases of stock-in-trade | D10: 541 | E10: 752 | F10: 960 | G10: 1565
A11: Changes in inventories of FG, WIP & stock-in-trade | D11: 161 | E11: 55 | F11: -144 | G11: -203
A12: Employee benefits expense | D12: 653 | E12: 743 | F12: 831 | G12: 916
A13: Finance costs | D13: 56 | E13: 73 | F13: 53 | G13: 53
A14: Depreciation & amortisation | D14: 155 | E14: 158 | F14: 178 | G14: 202
A15: Advertisement & sales promotion | D15: 842 | E15: 952 | F15: 1128 | G15: 1301
A16: Other expenses (excl. A&P) | D16: 1108 | E16: 1184 | F16: 1345 | G16: 1507
A17: Total expenses | D17: =SUM(D9:D16) -> 8165 | E17: =SUM(E9:E16) -> 7858 | F17: =SUM(F9:F16) -> 8923 | G17: =SUM(G9:G16) -> 11538
A18: Profit before tax | D18: =D8-D17 -> 1743 | E18: =E8-E17 -> 1937 | F18: =F8-F17 -> 2116 | G18: =G8-G17 -> 2277
A19: Current tax | D19: 377 | E19: 353 | F19: 480 | G19: 543
A20: Deferred tax charge / (credit) | D20: 44 | E20: 82 | F20: -22 | G20: -79
A21: Total tax expense | D21: =D19+D20 -> 421 | E21: =E19+E20 -> 435 | F21: =F19+F20 -> 458 | G21: =G19+G20 -> 464
A22: Profit for the year | D22: =D18-D21 -> 1322 | E22: =E18-E21 -> 1502 | F22: =F18-F21 -> 1658 | G22: =G18-G21 -> 1813
A23: Attributable to owners | D23: 1302 | E23: 1481 | F23: 1629 | G23: 1762
A24: Attributable to non-controlling interests | D24: =D22-D23 -> 20 | E24: =E22-E23 -> 21 | F24: =F22-F23 -> 29 | G24: =G22-G23 -> 51
A25: Memo: EBITDA (Revenue less operating costs, excl. other income) | C25: 1681 | D25: =D6-SUM(D9:D12)-D15-D16 -> 1810 | E25: =E6-SUM(E9:E12)-E15-E16 -> 2026 | F25: =F6-SUM(F9:F12)-F15-F16 -> 2139 | G25: =G6-SUM(G9:G12)-G15-G16 -> 2328
A26: Diluted EPS (₹, reported) | D26: 10.05 | E26: 11.43 | F26: 12.56 | G26: 13.59
A27: Note: FY22 full statements not retrieved from an official source; only revenue and EBITDA are shown. FX effect on cash shown separately for all years.
A28: BALANCE SHEET
A29: Property, plant & equipment | D29: 633 | E29: 700 | F29: 710 | G29: 832
A30: Capital work-in-progress | D30: 67 | E30: 44 | F30: 40 | G30: 85
A31: Right-of-use assets | D31: 175 | E31: 209 | F31: 230 | G31: 258
A32: Investment property | D32: 16 | E32: 15 | F32: 15 | G32: 9
A33: Goodwill | D33: 862 | E33: 863 | F33: 857 | G33: 1036
A34: Other intangible assets | D34: 560 | E34: 937 | F34: 946 | G34: 1498
A35: Non-current investments | D35: 518 | E35: 343 | F35: 215 | G35: 135
A36: Non-current loans | D36: 4 | E36: 4 | F36: 6 | G36: 4
A37: Other non-current financial assets | D37: 32 | E37: 100 | F37: 22 | G37: 27
A38: Deferred tax assets (net) | D38: 146 | E38: 68 | F38: 57 | G38: 125
A39: Non-current tax assets (net) | D39: 67 | E39: 95 | F39: 108 | G39: 114
A40: Other non-current assets | D40: 46 | E40: 40 | F40: 49 | G40: 92
A41: Total non-current assets | D41: =SUM(D29:D40) -> 3126 | E41: =SUM(E29:E40) -> 3418 | F41: =SUM(F29:F40) -> 3255 | G41: =SUM(G29:G40) -> 4215
...

Sheet Model
A1: Marico Limited – Integrated Three-Statement Model
A2: ₹ crore unless stated | FY ends 31 March | Historicals linked from 'Historicals' (green); forecasts driven by 'Assumptions' selected case
A4: ₹ crore | C4: FY22A | D4: FY23A | E4: FY24A | F4: FY25A | G4: FY26A | H4: FY27E | I4: FY28E | J4: FY29E | K4: FY30E | L4: FY31E
C5: Actual | D5: Actual | E5: Actual | F5: Actual | G5: Actual | H5: Forecast | I5: Forecast | J5: Forecast | K5: Forecast | L5: Forecast
A7: REVENUE BUILD
A8: India revenue | F8: =Historicals!F121 -> 8110 | G8: =Historicals!G121 -> 10348 | H8: =G8*(1+Assumptions!H7)*(1+Assumptions!H8) -> 11511.115 | I8: =H8*(1+Assumptions!I7)*(1+Assumptions!I8) -> 12686.4 | J8: =I8*(1+Assumptions!J7)*(1+Assumptions!J8) -> 14049.554 | K8: =J8*(1+Assumptions!K7)*(1+Assumptions!K8) -> 15486.472 | L8: =K8*(1+Assumptions!L7)*(1+Assumptions!L8) -> 16990.208
A9: growth % | G9: =G8/F8-1 -> 0.27595561 | H9: =H8/G8-1 -> 0.1124 | I9: =I8/H8-1 -> 0.1021 | J9: =J8/I8-1 -> 0.10745 | K9: =K8/J8-1 -> 0.102275 | L9: =L8/K8-1 -> 0.0971
A10: International revenue | F10: =Historicals!F122 -> 2721 | G10: =Historicals!G122 -> 3263 | H10: =G10*(1+Assumptions!H9)*(1+Assumptions!H10) -> 3714.9255 | I10: =H10*(1+Assumptions!I9)*(1+Assumptions!I10) -> 4155.8872 | J10: =I10*(1+Assumptions!J9)*(1+Assumptions!J10) -> 4608.0477 | K10: =J10*(1+Assumptions!K9)*(1+Assumptions!K10) -> 5063.7836 | L10: =K10*(1+Assumptions!L9)*(1+Assumptions!L10) -> 5514.4603
A11: growth % | G11: =G10/F10-1 -> 0.19919147 | H11: =H10/G10-1 -> 0.1385 | I11: =I10/H10-1 -> 0.1187 | J11: =J10/I10-1 -> 0.1088 | K11: =K10/J10-1 -> 0.0989 | L11: =L10/K10-1 -> 0.089
A12: Revenue from operations | C12: =Historicals!C6 -> 9512 | D12: =Historicals!D6 -> 9764 | E12: =Historicals!E6 -> 9653 | F12: =Historicals!F6 -> 10831 | G12: =Historicals!G6 -> 13611 | H12: =H8+H10 -> 15226.041 | I12: =I8+I10 -> 16842.287 | J12: =J8+J10 -> 18657.601 | K12: =K8+K10 -> 20550.255 | L12: =L8+L10 -> 22504.669
A13: growth % | D13: =D12/C12-1 -> 0.026492851 | E13: =E12/D12-1 -> -0.011368292 | F13: =F12/E12-1 -> 0.1220346 | G13: =G12/F12-1 -> 0.25667067 | H13: =H12/G12-1 -> 0.11865702 | I13: =I12/H12-1 -> 0.10615015 | J13: =J12/I12-1 -> 0.10778312 | K13: =K12/J12-1 -> 0.10144144 | L13: =L12/K12-1 -> 0.095104081
A15: INCOME STATEMENT
A16: Revenue from operations | C16: =C12 -> 9512 | D16: =D12 -> 9764 | E16: =E12 -> 9653 | F16: =F12 -> 10831 | G16: =G12 -> 13611 | H16: =H12 -> 15226.041 | I16: =I12 -> 16842.287 | J16: =J12 -> 18657.601 | ... L16: =L12 -> 22504.669
A17: Material cost | D17: =Historicals!D9+Historicals!D10+Historicals!D11 -> 5351 | E17: =Historicals!E9+Historicals!E10+Historicals!E11 -> 4748 | F17: =Historicals!F9+Historicals!F10+Historicals!F11 -> 5388 | G17: =Historicals!G9+Historicals!G10+Historicals!G11 -> 7559 | H17: =H16*Assumptions!H11 -> 8145.9318 | I17: =I16*Assumptions!I11 -> 8842.2008 | J17: =J16*Assumptions!J11 -> 9701.9527 | K17: =K16*Assumptions!K11 -> 10686.133 | L17: =L16*Assumptions!L11 -> 11702.428
A18: Gross profit | D18: =D16-D17 -> 4413 | E18: =E16-E17 -> 4905 | F18: =F16-F17 -> 5443 | G18: =G16-G17 -> 6052 | H18: =H16-H17 -> 7080.1089 | I18: =I16-I17 -> 8000.0864 | J18: =J16-J17 -> 8955.6487 | K18: =K16-K17 -> 9864.1226 | L18: =L16-L17 -> 10802.241
A19: Gross margin % | D19: =D18/D16 -> 0.45196641 | E19: =E18/E16 -> 0.50813219 | F19: =F18/F16 -> 0.50253901 | G19: =G18/G16 -> 0.44464036 | H19: =H18/H16 -> 0.465 | I19: =I18/I16 -> 0.475 | J19: =J18/J16 -> 0.48 | K19: =K18/K16 -> 0.48 | L19: =L18/L16 -> 0.48
A20: Advertising & sales promotion | D20: =Historicals!D15 -> 842 | E20: =Historicals!E15 -> 952 | F20: =Historicals!F15 -> 1128 | G20: =Historicals!G15 -> 1301 | H20: =H16*Assumptions!H12 -> 1568.2822 | I20: =I16*Assumptions!I12 -> 1734.7556 | J20: =J16*Assumptions!J12 -> 1921.7329 | K20: =K16*Assumptions!K12 -> 2116.6763 | L20: =L16*Assumptions!L12 -> 2317.9809
A21: Employee cost | D21: =Historicals!D12 -> 653 | E21: =Historicals!E12 -> 743 | F21: =Historicals!F12 -> 831 | G21: =Historicals!G12 -> 916 | H21: =H16*Assumptions!H13 -> 1035.3708 | I21: =I16*Assumptions!I13 -> 1145.2755 | J21: =J16*Assumptions!J13 -> 1268.7169 | K21: =K16*Assumptions!K13 -> 1397.4174 | L21: =L16*Assumptions!L13 -> 1530.3175
A22: Other expenses (excl. A&P) | D22: =Historicals!D16 -> 1108 | E22: =Historicals!E16 -> 1184 | F22: =Historicals!F16 -> 1345 | G22: =Historicals!G16 -> 1507 | H22: =H16*Assumptions!H14 -> 1720.5426 | I22: =I16*Assumptions!I14 -> 1903.1785 | J22: =J16*Assumptions!J14 -> 2108.309 | K22: =K16*Assumptions!K14 -> 2322.1789 | L22: =L16*Assumptions!L14 -> 2543.0276
A23: EBITDA | C23: =Historicals!C25 -> 1681 | D23: =D18-D20-D21-D22 -> 1810 | E23: =E18-E20-E21-E22 -> 2026 | F23: =F18-F20-F21-F22 -> 2139 | G23: =G18-G20-G21-G22 -> 2328 | H23: =H18-H20-H21-H22 -> 2755.9134 | I23: =I18-I20-I21-I22 -> 3216.8769 | J23: =J18-J20-J21-J22 -> 3656.8899 | K23: =K18-K20-K21-K22 -> 4027.8501 | L23: =L18-L20-L21-L22 -> 4410.915
A24: EBITDA margin % | C24: =C23/C16 -> 0.17672414 | D24: =D23/D16 -> 0.18537485 | E24: =E23/E16 -> 0.20988294 | F24: =F23/F16 -> 0.19748869 | G24: =G23/G16 -> 0.17103813 | H24: =H23/H16 -> 0.181 | I24: =I23/I16 -> 0.191 | J24: =J23/J16 -> 0.196 | ... L24: =L23/L16 -> 0.196
A25: Depreciation & amortisation | D25: =Historicals!D14 -> 155 | E25: =Historicals!E14 -> 158 | F25: =Historicals!F14 -> 178 | G25: =Historicals!G14 -> 202 | H25: =H16*Assumptions!H15 -> 236.00363 | I25: =I16*Assumptions!I15 -> 261.05545 | J25: =J16*Assumptions!J15 -> 289.19282 | K25: =K16*Assumptions!K15 -> 318.52896 | L25: =L16*Assumptions!L15 -> 348.82236
A26: EBIT | D26: =D23-D25 -> 1655 | E26: =E23-E25 -> 1868 | F26: =F23-F25 -> 1961 | G26: =G23-G25 -> 2126 | H26: =H23-H25 -> 2519.9097 | I26: =I23-I25 -> 2955.8214 | J26: =J23-J25 -> 3367.6971 | K26: =K23-K25 -> 3709.3211 | L26: =L23-L25 -> 4062.0927
A27: EBIT margin % | D27: =D26/D16 -> 0.1695002 | E27: =E26/E16 -> 0.19351497 | F27: =F26/F16 -> 0.18105438 | G27: =G26/G16 -> 0.15619719 | H27: =H26/H16 -> 0.1655 | I27: =I26/I16 -> 0.1755 | J27: =J26/J16 -> 0.1805 | K27: =K26/K16 -> 0.1805 | L27: =L26/L16 -> 0.1805
A28: Other income | D28: =Historicals!D7 -> 144 | E28: =Historicals!E7 -> 142 | F28: =Historicals!F7 -> 208 | G28: =Historicals!G7 -> 204 | H28: =Assumptions!H26*(G40+G41) -> 180.32 | I28: =Assumptions!I26*(H40+H41) -> 177.63763 | J28: =Assumptions!J26*(I40+I41) -> 193.51517 | K28: =Assumptions!K26*(J40+J41) -> 211.97058 | L28: =Assumptions!L26*(K40+K41) -> 232.92516
A29: Finance costs | D29: =Historicals!D13 -> 56 | E29: =Historicals!E13 -> 73 | F29: =Historicals!F13 -> 53 | G29: =Historicals!G13 -> 53 | H29: =Assumptions!H27*(G51+G52) -> 50.13 | I29: =Assumptions!I27*(H51+H52) -> 50.13 | J29: =Assumptions!J27*(I51+I52) -> 50.13 | K29: =Assumptions!K27*(J51+J52) -> 50.13 | L29: =Assumptions!L27*(K51+K52) -> 50.13
A30: Profit before tax | D30: =D26+D28-D29 -> 1743 | E30: =E26+E28-E29 -> 1937 | F30: =F26+F28-F29 -> 2116 | G30: =G26+G28-G29 -> 2277 | H30: =H26+H28-H29 -> 2650.0997 | I30: =I26+I28-I29 -> 3083.329 | J30: =J26+J28-J29 -> 3511.0822 | K30: =K26+K28-K29 -> 3871.1617 | L30: =L26+L28-L29 -> 4244.8878
A31: Tax expense | D31: =Historicals!D21 -> 421 | E31: =Historicals!E21 -> 435 | F31: =Historicals!F21 -> 458 | G31: =Historicals!G21 -> 464 | H31: =H30*Assumptions!H22 -> 609.52294 | I31: =I30*Assumptions!I22 -> 709.16568 | J31: =J30*Assumptions!J22 -> 807.54891 | K31: =K30*Assumptions!K22 -> 890.36719 | L31: =L30*Assumptions!L22 -> 976.32421
A32: Effective tax rate % | D32: =D31/D30 -> 0.24153758 | E32: =E31/E30 -> 0.22457408 | F32: =F31/F30 -> 0.21644612 | G32: =G31/G30 -> 0.2037769 | H32: =H31/H30 -> 0.23 | I32: =I31/I30 -> 0.23 | J32: =J31/J30 -> 0.23 | K32: =K31/K30 -> 0.23 | L32: =L31/L30 -> 0.23
A33: Profit after tax | D33: =D30-D31 -> 1322 | E33: =E30-E31 -> 1502 | F33: =F30-F31 -> 1658 | G33: =G30-G31 -> 1813 | H33: =H30-H31 -> 2040.5768 | I33: =I30-I31 -> 2374.1634 | J33: =J30-J31 -> 2703.5333 | K33: =K30-K31 -> 2980.7945 | L33: =L30-L31 -> 3268.5636
A34: Non-controlling interests | D34: =Historicals!D24 -> 20 | E34: =Historicals!E24 -> 21 | F34: =Historicals!F24 -> 29 | G34: =Historicals!G24 -> 51 | H34: =H33*Assumptions!H23 -> 51.01442 | I34: =I33*Assumptions!I23 -> 59.354084 | J34: =J33*Assumptions!J23 -> 67.588333 | K34: =K33*Assumptions!K23 -> 74.519862 | L34: =L33*Assumptions!L23 -> 81.714091
A35: PAT attributable to owners | D35: =D33-D34 -> 1302 | E35: =E33-E34 -> 1481 | F35: =F33-F34 -> 1629 | G35: =G33-G34 -> 1762 | H35: =H33-H34 -> 1989.5624 | I35: =I33-I34 -> 2314.8093 | J35: =J33-J34 -> 2635.945 | K35: =K33-K34 -> 2906.2746 | L35: =L33-L34 -> 3186.8496
A36: Net margin (owners) % | D36: =D35/D16 -> 0.13334699 | E36: =E35/E16 -> 0.15342381 | F36: =F35/F16 -> 0.15040162 | G36: =G35/G16 -> 0.12945412 | H36: =H35/H16 -> 0.1306684 | I36: =I35/I16 -> 0.13744032 | J36: =J35/J16 -> 0.14127995 | K36: =K35/K16 -> 0.1414228 | L36: =L35/L16 -> 0.14160838
A37: Diluted EPS (₹) | D37: =Historicals!D26 -> 10.05 | E37: =Historicals!E26 -> 11.43 | F37: =Historicals!F26 -> 12.56 | G37: =Historicals!G26 -> 13.59 | H37: =H35*10/WACC!$C$20 -> 15.292991 | I37: =I35*10/WACC!$C$20 -> 17.793038 | J37: =J35*10/WACC!$C$20 -> 20.261483 | K37: =K35*10/WACC!$C$20 -> 22.339401 | L37: =L35*10/WACC!$C$20 -> 24.496072
A39: BALANCE SHEET (CONDENSED)
A40: Cash & cash equivalents | D40: =Historicals!D45 -> 207 | E40: =Historicals!E45 -> 228 | F40: =Historicals!F45 -> 321 | G40: =Historicals!G45 -> 404 | H40: =H82 -> 365.68049 | I40: =I82 -> 592.50246 | J40: =J82 -> 856.15112 | K40: =K82 -> 1155.5023 | L40: =L82 -> 1493.4248
A41: Treasury investments & bank balances | D41: =Historicals!D35+Historicals!D43+Historicals!D46 -> 1645 | E41: =Historicals!E35+Historicals!E43+Historicals!E46 -> 1317 | F41: =Historicals!F35+Historicals!F43+Historicals!F46 -> 2046 | G41: =Historicals!G35+Historicals!G43+Historicals!G46 -> 2172 | H41: =G41 -> 2172 | I41: =H41 -> 2172 | J41: =I41 -> 2172 | K41: =J41 -> 2172 | L41: =K41 -> 2172
A42: Trade receivables | D42: =Historicals!D44 -> 1015 | E42: =Historicals!E44 -> 1069 | F42: =Historicals!F44 -> 1271 | G42: =Historicals!G44 -> 1304 | H42: =H16*Assumptions!H17/365 -> 1543.4617 | I42: =I16*Assumptions!I17/365 -> 1707.3003 | J42: =J16*Assumptions!J17/365 -> 1891.3185 | K42: =K16*Assumptions!K17/365 -> 2083.1766 | L42: =L16*Assumptions!L17/365 -> 2281.2952
A43: Inventories | D43: =Historicals!D42 -> 1225 | E43: =Historicals!E42 -> 1336 | F43: =Historicals!F42 -> 1235 | G43: =Historicals!G42 -> 1611 | H43: =H17*Assumptions!H18/365 -> 1785.4097 | I43: =I17*Assumptions!I18/365 -> 1938.0166 | J43: =J17*Assumptions!J18/365 -> 2126.4554 | K43: =K17*Assumptions!K18/365 -> 2342.1661 | L43: =L17*Assumptions!L18/365 -> 2564.9157
A44: Other current assets | D44: =SUM(Historicals!D47:D50) -> 246 | E44: =SUM(Historicals!E47:E50) -> 396 | F44: =SUM(Historicals!F47:F50) -> 419 | G44: =SUM(Historicals!G47:G50) -> 504 | H44: =H16*Assumptions!H20 -> 563.36351 | I44: =I16*Assumptions!I20 -> 623.16463 | J44: =J16*Assumptions!J20 -> 690.33125 | K44: =K16*Assumptions!K20 -> 760.35945 | L44: =L16*Assumptions!L20 -> 832.67274
...

Sheet WACC
A1: Marico Limited – Weighted Average Cost of Capital
A2: Blue = input (source / rationale in column D) | Market data as at 22–23 Oct 2026
A4: COST OF EQUITY (CAPM) | D4: Source / rationale
A5: Risk-free rate (India 10-year G-sec yield) | C5: 0.0747 | D5: Trading Economics (unofficial), 23-Oct-2026 – verify vs RBI/CCIL
A6: Raw equity beta (observed) | C6: 0.51 | D6: Business Today stock page (unofficial) – verify vs Bloomberg/NSE
A7: Adjusted beta (Blume: 0.67 × raw + 0.33) | C7: =0.67*C6+0.33 -> 0.6717 | D7: Blume adjustment toward 1.0
A8: Equity risk premium (India) | C8: 0.06 | D8: Analyst assumption (India ERP range 5.5–7.5%)
A9: Cost of equity | C9: =C5+C7*C8 -> 0.115002
A11: COST OF DEBT
A12: Pre-tax cost of debt | C12: 0.08 | D12: Assumption: AAA issuer, ~50bp over G-sec
A13: Marginal tax rate (India corporate, incl. surcharge & cess) | C13: 0.25168 | D13: Sec. 115BAA: 22% + 10% surcharge + 4% cess
A14: After-tax cost of debt | C14: =C12*(1-C13) -> 0.0598656
A16: CAPITAL STRUCTURE (MARKET VALUES)
A17: Share price (₹) | C17: 775 | D17: NSE close 22-Oct-2026 via Trendlyne (unofficial) – verify vs NSE
A18: Equity shares outstanding (mn) | C18: 1298.1489 | D18: Annual Report FY26, Note 12(a) – 31-Mar-2026
A19: Dilutive share options (mn) | C19: 2.814589 | D19: Annual Report FY26, Note 36 (EPS) – dilutive options
A20: Diluted shares (mn) | C20: =C18+C19 -> 1300.9635
A21: Market capitalisation (₹ cr) | C21: =C17*C20/10 -> 100824.67
A22: Gross debt incl. lease liabilities (₹ cr, 31-Mar-26) | C22: =Model!G51+Model!G52 -> 557
A23: Total capital (₹ cr) | C23: =C21+C22 -> 101381.67
A24: Equity weight | C24: =C21/C23 -> 0.99450591
A25: Debt weight | C25: =C22/C23 -> 0.0054940896
A27: WEIGHTED AVERAGE COST OF CAPITAL | C27: =C24*C9+C25*C14 -> 0.11469908

Sheet DCF
A1: Marico Limited – DCF Valuation (Unlevered FCF, Perpetual Growth)
A2: ₹ crore unless stated | Mid-year discounting from valuation date | Black = formula, green = link, blue = input
A4: KEY INPUTS
A5: Valuation date | C5: =DATE(2026,10,23) -> 46318 | D5: Date of analysis; bridge items are as at 31-Mar-2026 (latest audited balance sheet)
A6: Scenario | C6: =Assumptions!D3 -> Base case
A7: WACC | C7: =WACC!C27 -> 0.11469908
A8: Terminal growth rate | C8: =Assumptions!H29 -> 0.06
A9: Current share price (₹) | C9: =WACC!C17 -> 775
A10: Diluted shares (mn) | C10: =WACC!C20 -> 1300.9635
A12: UNLEVERED FREE CASH FLOW
A13: ₹ crore | C13: FY27E | D13: FY28E | E13: FY29E | F13: FY30E | G13: FY31E
A14: Fiscal year end | C14: =DATE(2027,3,31) -> 46477 | D14: =EDATE(C14,12) -> 46843 | E14: =EDATE(D14,12) -> 47208 | F14: =EDATE(E14,12) -> 47573 | G14: =EDATE(F14,12) -> 47938
A15: Revenue | C15: =Model!H16 -> 15226.041 | D15: =Model!I16 -> 16842.287 | E15: =Model!J16 -> 18657.601 | F15: =Model!K16 -> 20550.255 | G15: =Model!L16 -> 22504.669
A16: EBITDA | C16: =Model!H23 -> 2755.9134 | D16: =Model!I23 -> 3216.8769 | E16: =Model!J23 -> 3656.8899 | F16: =Model!K23 -> 4027.8501 | G16: =Model!L23 -> 4410.915
A17: EBITDA margin % | C17: =C16/C15 -> 0.181 | D17: =D16/D15 -> 0.191 | E17: =E16/E15 -> 0.196 | F17: =F16/F15 -> 0.196 | G17: =G16/G15 -> 0.196
A18: Depreciation & amortisation | C18: =Model!H25 -> 236.00363 | D18: =Model!I25 -> 261.05545 | E18: =Model!J25 -> 289.19282 | F18: =Model!K25 -> 318.52896 | G18: =Model!L25 -> 348.82236
A19: EBIT | C19: =Model!H26 -> 2519.9097 | D19: =Model!I26 -> 2955.8214 | E19: =Model!J26 -> 3367.6971 | F19: =Model!K26 -> 3709.3211 | G19: =Model!L26 -> 4062.0927
A20: Tax rate on EBIT | C20: =Model!H32 -> 0.23 | D20: =Model!I32 -> 0.23 | E20: =Model!J32 -> 0.23 | F20: =Model!K32 -> 0.23 | G20: =Model!L32 -> 0.23
A21: (–) Taxes on EBIT | C21: =-C19*C20 -> -579.57924 | D21: =-D19*D20 -> -679.83892 | E21: =-E19*E20 -> -774.57032 | F21: =-F19*F20 -> -853.14386 | G21: =-G19*G20 -> -934.28132
A22: NOPAT | C22: =C19+C21 -> 1940.3305 | D22: =D19+D21 -> 2275.9825 | E22: =E19+E21 -> 2593.1267 | F22: =F19+F21 -> 2856.1773 | G22: =G19+G21 -> 3127.8114
A23: (+) Depreciation & amortisation | C23: =C18 -> 236.00363 | D23: =D18 -> 261.05545 | E23: =E18 -> 289.19282 | F23: =F18 -> 318.52896 | G23: =G18 -> 348.82236
A24: (–) Capex | C24: =Model!H71 -> -334.9729 | D24: =Model!I71 -> -370.53032 | E24: =Model!J71 -> -410.46723 | F24: =Model!K71 -> -452.10562 | G24: =Model!L71 -> -495.10271
A25: (–) Increase in net working capital | C25: =SUM(Model!H65:H69) -> -337.26272 | D25: =SUM(Model!I65:I69) -> -126.66502 | E25: =SUM(Model!J65:J69) -> -142.26593 | F25: =SUM(Model!K65:K69) -> -148.32704 | G25: =SUM(Model!L65:L69) -> -153.16709
A26: Unlevered free cash flow | C26: =C22+C23+C24+C25 -> 1504.0985 | D26: =D22+D23+D24+D25 -> 2039.8426 | E26: =E22+E23+E24+E25 -> 2329.5864 | F26: =F22+F23+F24+F25 -> 2574.2736 | G26: =G22+G23+G24+G25 -> 2828.3639
A27: Year fraction included (stub for FY27E) | C27: =MAX(0,MIN(1,(C14-$C$5)/365)) -> 0.43561644 | D27: =MAX(0,MIN(1,(D14-$C$5)/365)) -> 1 | E27: =MAX(0,MIN(1,(E14-$C$5)/365)) -> 1 | F27: =MAX(0,MIN(1,(F14-$C$5)/365)) -> 1 | G27: =MAX(0,MIN(1,(G14-$C$5)/365)) -> 1
A28: Discount period (mid-year) | C28: =SUM($C27:C27)-C27/2 -> 0.21780822 | D28: =SUM($C27:D27)-D27/2 -> 0.93561644 | E28: =SUM($C27:E27)-E27/2 -> 1.9356164 | F28: =SUM($C27:F27)-F27/2 -> 2.9356164 | G28: =SUM($C27:G27)-G27/2 -> 3.9356164
A29: Discount factor | C29: =1/(1+$C$7)^C28 -> 0.97662689 | D29: =1/(1+$C$7)^D28 -> 0.90339678 | E29: =1/(1+$C$7)^E28 -> 0.81044005 | F29: =1/(1+$C$7)^F28 -> 0.72704828 | G29: =1/(1+$C$7)^G28 -> 0.65223727
A30: PV of unlevered FCF | C30: =C26*C27*C29 -> 639.89574 | D30: =D26*D27*D29 -> 1842.7872 | E30: =E26*E27*E29 -> 1887.9901 | F30: =F26*F27*F29 -> 1871.6212 | G30: =G26*G27*G29 -> 1844.7644
A32: TERMINAL VALUE
A33: Terminal-year unlevered FCF (FY31E) | C33: =G26 -> 2828.3639
A34: Terminal growth rate | C34: =C8 -> 0.06
A35: Terminal value at end-FY31E | C35: =C33*(1+C34)/(C7-C34) -> 54810.172
A36: Discount period (end-FY31E) | C36: =SUM(C27:G27) -> 4.4356164
A37: PV of terminal value | C37: =C35/(1+C7)^C36 -> 33860.078
A38: Implied terminal EV / EBITDA (FY31E) | C38: =C35/G16 -> 12.426032
A39: Note: FY27E includes only the cash flow from the valuation date to 31-Mar-27 (stub). Bridge items are at 31-Mar-26; cash generated Apr–Oct 2026 is therefore excluded (conservative).
A41: EQUITY VALUE BRIDGE
A42: PV of explicit-period FCF | C42: =SUM(C30:G30) -> 8087.0586
A43: PV of terminal value | C43: =C37 -> 33860.078
A44: Enterprise value | C44: =C42+C43 -> 41947.137
...

Sheet Checks
A1: Marico Limited – Model Integrity Checks
A2: Differences should be zero (₹ crore). Status = OK when every period is within ±0.5.
A4: Check | C4: FY22A | D4: FY23A | E4: FY24A | F4: FY25A | G4: FY26A | H4: FY27E | I4: FY28E | J4: FY29E | K4: FY30E | L4: FY31E | M4: Status
A5: INTEGRITY CHECKS
A6: Historicals: total assets less equity & liabilities | D6: =Historicals!D78 -> 0 | E6: =Historicals!E78 -> 0 | F6: =Historicals!F78 -> 0 | G6: =Historicals!G78 -> 0 | M6: {=IF(SUMPRODUCT(ABS(N(+C6:L6)))<0.5,"OK","ERROR")} -> OK
A7: Historicals: computed total assets less reported total assets | D7: =Historicals!D52-Historicals!D81 -> 0 | E7: =Historicals!E52-Historicals!E81 -> 0 | F7: =Historicals!F52-Historicals!F81 -> 0 | G7: =Historicals!G52-Historicals!G81 -> 0 | M7: {=IF(SUMPRODUCT(ABS(N(+C7:L7)))<0.5,"OK","ERROR")} -> OK
A8: Historicals: cash-flow closing cash less balance-sheet cash | D8: =Historicals!D117 -> 0 | E8: =Historicals!E117 -> 0 | F8: =Historicals!F117 -> 0 | G8: =Historicals!G117 -> 0 | M8: {=IF(SUMPRODUCT(ABS(N(+C8:L8)))<0.5,"OK","ERROR")} -> OK
A9: Historicals: P&L profit before tax less cash-flow PBT | D9: =Historicals!D18-Historicals!D83 -> 0 | E9: =Historicals!E18-Historicals!E83 -> 0 | F9: =Historicals!F18-Historicals!F83 -> 0 | G9: =Historicals!G18-Historicals!G83 -> 0 | M9: {=IF(SUMPRODUCT(ABS(N(+C9:L9)))<0.5,"OK","ERROR")} -> OK
A10: Historicals: segment revenue less total revenue | F10: =Historicals!F124 -> 0 | G10: =Historicals!G124 -> 0 | M10: {=IF(SUMPRODUCT(ABS(N(+C10:L10)))<0.5,"OK","ERROR")} -> OK
A11: Model: balance sheet balances (assets less L&E) | D11: =Model!D60 -> 0 | E11: =Model!E60 -> 0 | F11: =Model!F60 -> 0 | G11: =Model!G60 -> 0 | H11: =Model!H60 -> 0 | I11: =Model!I60 -> 0 | J11: =Model!J60 -> 0 | K11: =Model!K60 -> 0 | L11: =Model!L60 -> 0 | M11: {=IF(SUMPRODUCT(ABS(N(+C11:L11)))<0.5,"OK","ERROR")} -> OK
A12: Model: cash-flow closing cash less balance-sheet cash | D12: =Model!D83 -> 0 | E12: =Model!E83 -> 0 | F12: =Model!F83 -> 0 | G12: =Model!G83 -> 0 | H12: =Model!H83 -> 0 | I12: =Model!I83 -> 0 | J12: =Model!J83 -> 0 | K12: =Model!K83 -> 0 | L12: =Model!L83 -> 0 | M12: {=IF(SUMPRODUCT(ABS(N(+C12:L12)))<0.5,"OK","ERROR")} -> OK
A13: Model: cash-flow net income less P&L net income | H13: =Model!H63-Model!H33 -> 0 | I13: =Model!I63-Model!I33 -> 0 | J13: =Model!J63-Model!J33 -> 0 | K13: =Model!K63-Model!K33 -> 0 | L13: =Model!L63-Model!L33 -> 0 | M13: {=IF(SUMPRODUCT(ABS(N(+C13:L13)))<0.5,"OK","ERROR")} -> OK
A14: Model: owners' equity roll-forward (opening + PAT – dividends – closing) | H14: =Model!G56+Model!H35+Model!H75-Model!H56 -> 0 | I14: =Model!H56+Model!I35+Model!I75-Model!I56 -> 0 | J14: =Model!I56+Model!J35+Model!J75-Model!J56 -> 0 | K14: =Model!J56+Model!K35+Model!K75-Model!K56 -> 0 | L14: =Model!K56+Model!L35+Model!L75-Model!L56 -> 0 | M14: {=IF(SUMPRODUCT(ABS(N(+C14:L14)))<0.5,"OK","ERROR")} -> OK
A15: Model: historical PBT less reported PBT | D15: =Model!D30-Historicals!D18 -> 0 | E15: =Model!E30-Historicals!E18 -> 0 | F15: =Model!F30-Historicals!F18 -> 0 | G15: =Model!G30-Historicals!G18 -> 0 | M15: {=IF(SUMPRODUCT(ABS(N(+C15:L15)))<0.5,"OK","ERROR")} -> OK
A16: Model: historical EBITDA less reported EBITDA | C16: =Model!C23-Historicals!C25 -> 0 | D16: =Model!D23-Historicals!D25 -> 0 | E16: =Model!E23-Historicals!E25 -> 0 | F16: =Model!F23-Historicals!F25 -> 0 | G16: =Model!G23-Historicals!G25 -> 0 | M16: {=IF(SUMPRODUCT(ABS(N(+C16:L16)))<0.5,"OK","ERROR")} -> OK
A17: Model: forecast revenue less segment build | H17: =Model!H16-Model!H8-Model!H10 -> 0 | I17: =Model!I16-Model!I8-Model!I10 -> 0 | J17: =Model!J16-Model!J8-Model!J10 -> 0 | K17: =Model!K16-Model!K8-Model!K10 -> 0 | L17: =Model!L16-Model!L8-Model!L10 -> 0 | M17: {=IF(SUMPRODUCT(ABS(N(+C17:L17)))<0.5,"OK","ERROR")} -> OK
A18: DCF: sensitivity 1 centre less implied value per share | C18: =ROUND(DCF!E65-DCF!C54,6) -> 0 | M18: {=IF(SUMPRODUCT(ABS(N(+C18:L18)))<0.5,"OK","ERROR")} -> OK
A19: DCF: sensitivity 2 centre less implied value per share | C19: =ROUND(DCF!E73-DCF!C54,6) -> 0 | M19: {=IF(SUMPRODUCT(ABS(N(+C19:L19)))<0.5,"OK","ERROR")} -> OK
A20: DCF: terminal growth below WACC (1 = breach) | C20: =IF(DCF!C8<DCF!C7,0,1) -> 0 | M20: {=IF(SUMPRODUCT(ABS(N(+C20:L20)))<0.5,"OK","ERROR")} -> OK
A21: DCF: terminal growth below risk-free rate (1 = breach) | C21: =IF(DCF!C8<WACC!C5,0,1) -> 0 | M21: {=IF(SUMPRODUCT(ABS(N(+C21:L21)))<0.5,"OK","ERROR")} -> OK
A22: DCF: WACC sheet shares agree to DCF shares | C22: =WACC!C20-DCF!C53 -> 0 | M22: {=IF(SUMPRODUCT(ABS(N(+C22:L22)))<0.5,"OK","ERROR")} -> OK
A24: Warning flags (not errors)
A25: DCF: terminal value share of EV above 75% | C25: =DCF!C45 -> 0.80720833 | M25: =IF(C25>0.75,"REVIEW","OK") -> REVIEW
A26: Model: forecast net cash / (debt) negative in any year | C26: =MIN(Model!H103:L103) -> 1980.6805 | M26: =IF(C26<0,"REVIEW","OK") -> OK
A28: MASTER CHECK | M28: =IF(COUNTIF(M6:M22,"ERROR")=0,"ALL CHECKS PASS","ERRORS – REVIEW") -> ALL CHECKS PASS
